Workbook

Sheet Ranking Geral
A1: RANKING 0 a 50m³ | B1: Nome do Posto | C1: Pontos Cursos | D1: Pontos Combustíveis | E1: Total Geral | G1: Posto Nacional | H1: =Cursos!N4 -> 0 | I1: =Litragem!N3 -> 0 | J1: =H1+I1 -> 0
A2: 1 | B2: 7784 - ROSANE BERSCH HARTWIG ME - FILIAL 01 | C2: =Cursos!N4 -> 0 | D2: =Litragem!N3 -> 0 | E2: =SUM(C2+D2) -> 0 | G2: Posto Tomazi | H2: =Cursos!N5 -> 12 | I2: =Litragem!N4 -> 0 | J2: =H2+I2 -> 12
A3: 2 | B3: 13968 - MARIA DAS MERCES DE SA OLIVEIRA BATISTA DE ABREU LTDA MATRIZ | C3: =Cursos!N20 -> 0 | D3: =Litragem!N19 -> 0 | E3: =SUM(C3+D3) -> 0 | G3: Posto Nacional 2 | H3: =Cursos!N6 -> 0 | I3: =Litragem!N5 -> 0 | J3: =H3+I3 -> 0
A4: 3 | B4: 11928 - MARCOS ALFREDO POZZEBON | C4: =Cursos!N5 -> 12 | D4: =Litragem!N4 -> 0 | E4: =SUM(C4+D4) -> 12 | G4: Auto Posto Cajati 230 | H4: =Cursos!N7 -> 0 | I4: =Litragem!N6 -> 0 | J4: =H4+I4 -> 0
A5: 4 | B5: 11386 - COMERCIO DE COMBUSTIVEIS ITATIBENSE LTDA | C5: =Cursos!N6 -> 0 | D5: =Litragem!N5 -> 0 | E5: =SUM(C5+D5) -> 0 | G5: Barão | H5: =Cursos!N8 -> 12 | I5: =Litragem!N7 -> 0 | J5: =H5+I5 -> 12
A6: 5 | B6: 10389 - AUTO POSTO ABREU LTDA | C6: =Cursos!N7 -> 0 | D6: =Litragem!N6 -> 0 | E6: =SUM(C6+D6) -> 0 | G6: Posto de Combustíveis | H6: =Cursos!N9 -> 0 | I6: =Litragem!N8 -> 0 | J6: =H6+I6 -> 0
A7: 6 | B7: 3999 - POSTO ROSINSKI LTDA | C7: =Cursos!N8 -> 12 | D7: =Litragem!N7 -> 0 | E7: =SUM(C7+D7) -> 12
A8: 7 | B8: 1283 - MARILEI DE FATIMA ALT LTDA | C8: =Cursos!N9 -> 0 | D8: =Litragem!N8 -> 0 | E8: =SUM(C8+D8) -> 0
A9: 8 | B9: 4735 - AUTO POSTO CASTELLO LTDA | C9: =Cursos!N10 -> 12 | D9: =Litragem!N9 -> 0 | E9: =SUM(C9+D9) -> 12
A10: 9 | B10: 8622 - COOP MISTA DA AGRIC FAMILIAR DE SAO JOAO DO OESTE COOPAFASJO | C10: =Cursos!N11 -> 12 | D10: =Litragem!N10 -> 0 | E10: =SUM(C10+D10) -> 12
A11: 10 | B11: 2664 - AUTO POSTO ANCHIETA LTDA | C11: =Cursos!N12 -> 0 | D11: =Litragem!N11 -> 0 | E11: =SUM(C11+D11) -> 0
A12: 11 | B12: 6357 - AUTO POSTO DIONISIO LTDA | C12: =Cursos!N13 -> 0 | D12: =Litragem!N12 -> 0 | E12: =SUM(C12+D12) -> 0
A13: 12 | B13: 11839 - COMERCIO DE COMBUSTIVEIS BARRA DO JACARE LTDA | C13: =Cursos!N14 -> 0 | D13: =Litragem!N13 -> 0 | E13: =SUM(C13+D13) -> 0
A14: 13 | B14: 13450 - DANIELI E DANIELI AUTO POSTO | C14: =Cursos!N15 -> 0 | D14: =Litragem!N14 -> 0 | E14: =SUM(C14+D14) -> 0
A15: 14 | B15: 4266 - POSTO XAVIER E XAVIER LTDA | C15: =Cursos!N16 -> 0 | D15: =Litragem!N15 -> 0 | E15: =SUM(C15+D15) -> 0
A16: 15 | B16: 12380 - LEKALL COMERCIO E DISTRIBUICAO DE COMBUSTIVEIS LTDA | C16: =Cursos!N17 -> 0 | D16: =Litragem!N16 -> 0 | E16: =SUM(C16+D16) -> 0
A17: 16 | B17: 667 - ANSILIERO E NAVA LTDA ME | C17: =Cursos!N18 -> 0 | D17: =Litragem!N17 -> 0 | E17: =SUM(C17+D17) -> 0
A18: 17 | B18: 12181 - POSTO JK DERIVADOS DE PETROLEO LTDA | C18: =Cursos!N19 -> 0 | D18: =Litragem!N18 -> 0 | E18: =SUM(C18+D18) -> 0
A19: 18 | B19: 13969 - MARIA DAS MERCES DE SA OLIVEIRA BATISTA DE ABREU LTDA FILIAL | C19: =Cursos!N21 -> 0 | D19: =Litragem!N20 -> 0 | E19: =SUM(C19+D19) -> 0
A20: 19 | B20: 8571 - COMERCIAL DE COMBUSTIVEIS RG LTDA | C20: =Cursos!N22 -> 0 | D20: =Litragem!N21 -> 0 | E20: =SUM(C20+D20) -> 0
A23: RANKING 51 a 100m³ | B23: Nome do Posto | C23: Pontos Cursos | D23: Pontos Combustíveis | E23: Total Geral
A24: 1 | B24: 11088 - POSTO CENTRAL GUARANIACU LTDA | C24: =Cursos!N23 -> 12 | D24: =Litragem!N22 -> 0 | E24: =SUM(C24+D24) -> 12
A25: 2 | B25: 5264 - AUTO POSTO BOM JESUS ITAIOPOLIS LTDA | C25: =Cursos!N24 -> 0 | D25: =Litragem!N23 -> 0 | E25: =SUM(C25+D25) -> 0
A26: 3 | B26: 11636 - PETROMULLER ABASTECEDORA CASCATA LTDA | C26: =Cursos!N25 -> 0 | D26: =Litragem!N24 -> 0 | E26: =SUM(C26+D26) -> 0
A27: 4 | B27: 11403 - POSTO SENHOR DO BONFIM LTDA | C27: =Cursos!N26 -> 0 | D27: =Litragem!N25 -> 0 | E27: =SUM(C27+D27) -> 0
A28: 5 | B28: 5149 - POSTO DE COMBUSTIVEIS PARQUE LTDA EPP | C28: =Cursos!N27 -> 0 | D28: =Litragem!N26 -> 0 | E28: =SUM(C28+D28) -> 0
A29: 6 | B29: 3139 - POSTO SANTOS E SILVA LTDA | C29: =Cursos!N28 -> 12 | D29: =Litragem!N27 -> 0 | E29: =SUM(C29+D29) -> 12
A30: 7 | B30: 5953 - COMERCIO DE COMBUSTIVEIS OLCZEWSKI LTDA EPP | C30: =Cursos!N29 -> 12 | D30: =Litragem!N28 -> 0 | E30: =SUM(C30+D30) -> 12
A31: 8 | B31: 14033 - HS COMERCIO DE COMBUSTIVEIS LTDA | C31: =Cursos!N30 -> 24 | D31: =Litragem!N29 -> 0 | E31: =SUM(C31+D31) -> 24
A32: 9 | B32: 13516 - AUTO POSTO FORTI CORSE LTDA | C32: =Cursos!N31 -> 0 | D32: =Litragem!N30 -> 0 | E32: =SUM(C32+D32) -> 0
A33: 10 | B33: 12305 - ROBERTO AZAMBUJA LTDA | C33: =Cursos!N32 -> 24 | D33: =Litragem!N31 -> 0 | E33: =SUM(C33+D33) -> 24
A34: 11 | B34: 6701 - AUTO POSTO MARIA RITA LTDA | C34: =Cursos!N33 -> 12 | D34: =Litragem!N32 -> 0 | E34: =SUM(C34+D34) -> 12
A35: 12 | B35: 9262 - EXCELENCIA EM COMBUSTIVEIS IRANI LTDA | C35: =Cursos!N34 -> 24 | D35: =Litragem!N33 -> 0 | E35: =SUM(C35+D35) -> 24
... A41: 18 | B41: POSTO BATEL LTDA | C41: =Cursos!N40 -> 0 | D41: =Litragem!N39 -> 0 | E41: =SUM(C41+D41) -> 0
A44: RANKING 101 a 200m³ | B44: Nome do Posto | C44: Pontos Cursos | D44: Pontos Combustíveis | E44: Total Geral
A45: 1 | B45: 4251 - AUTO POSTO RIO DO CAMPO LTDA | C45: =Cursos!N41 -> 0 | D45: =Litragem!N40 -> 0 | E45: =SUM(C45+D45) -> 0
A46: 2 | B46: 11069 - AUTO POSTO TREIS CORACOES LTDA | C46: =Cursos!N42 -> 0 | D46: =Litragem!N41 -> 0 | E46: =SUM(C46+D46) -> 0
A47: 3 | B47: 4506 - POSTO IPE AMARELO 5 | C47: =Cursos!N43 -> 12 | D47: =Litragem!N42 -> 0 | E47: =SUM(C47+D47) -> 12
A48: 4 | B48: 10798 - POSTO CAPIM LTDA | C48: =Cursos!N44 -> 24 | D48: =Litragem!N43 -> 0 | E48: =SUM(C48+D48) -> 24
A49: 5 | B49: 13888- POSTO RODA MAIS 9 | C49: =Cursos!N45 -> 0 | D49: =Litragem!N44 -> 0 | E49: =SUM(C49+D49) -> 0
...

Sheet Cursos
A1: Nome dos Postos | B1: Curso Carlos Bispo | H1: Curso Brasil Postos | N1: Total Pontos Cursos
B2: Abril | D2: Maio | F2: Junho | H2: Setembro | J2: Outubro | L2: Novembro
B3: 14 | C3: 22 | D3: 12 | E3: 19 | F3: 2 | G3: 9 | H3: 15 | I3: 29 | J3: 13 | K3: 27 | L3: 10 | M3: 24
A4: 7784 - ROSANE BERSCH HARTWIG ME - FILIAL 01 | N4: =COUNTIF(B4:G4,"AO VIVO")*12+COUNTIF(B4:G4,"EAD")*8+COUNTIF(H4:M4,"AO VIVO")*12+COUNTIF(H4:M4,"EAD")*8 -> 0
A5: 11928 - MARCOS ALFREDO POZZEBON | B5: AO VIVO | N5: =COUNTIF(B5:G5,"AO VIVO")*12+COUNTIF(B5:G5,"EAD")*8+COUNTIF(H5:M5,"AO VIVO")*12+COUNTIF(H5:M5,"EAD")*8 -> 12
A6: 11386 - COMERCIO DE COMBUSTIVEIS ITATIBENSE LTDA | N6: =COUNTIF(B6:G6,"AO VIVO")*12+COUNTIF(B6:G6,"EAD")*8+COUNTIF(H6:M6,"AO VIVO")*12+COUNTIF(H6:M6,"EAD")*8 -> 0
A7: 10389 - AUTO POSTO ABREU LTDA | N7: =COUNTIF(B7:G7,"AO VIVO")*12+COUNTIF(B7:G7,"EAD")*8+COUNTIF(H7:M7,"AO VIVO")*12+COUNTIF(H7:M7,"EAD")*8 -> 0
A8: 3999 - POSTO ROSINSKI LTDA | B8: AO VIVO | N8: =COUNTIF(B8:G8,"AO VIVO")*12+COUNTIF(B8:G8,"EAD")*8+COUNTIF(H8:M8,"AO VIVO")*12+COUNTIF(H8:M8,"EAD")*8 -> 12
A9: 1283 - MARILEI DE FATIMA ALT LTDA | N9: =COUNTIF(B9:G9,"AO VIVO")*12+COUNTIF(B9:G9,"EAD")*8+COUNTIF(H9:M9,"AO VIVO")*12+COUNTIF(H9:M9,"EAD")*8 -> 0
A10: 4735 - AUTO POSTO CASTELLO LTDA | B10: AO VIVO | N10: =COUNTIF(B10:G10,"AO VIVO")*12+COUNTIF(B10:G10,"EAD")*8+COUNTIF(H10:M10,"AO VIVO")*12+COUNTIF(H10:M10,"EAD")*8 -> 12
A11: 8622 - COOP MISTA DA AGRIC FAMILIAR DE SAO JOAO DO OESTE COOPAFASJO | B11: AO VIVO | N11: =COUNTIF(B11:G11,"AO VIVO")*12+COUNTIF(B11:G11,"EAD")*8+COUNTIF(H11:M11,"AO VIVO")*12+COUNTIF(H11:M11,"EAD")*8 -> 12
A12: 2664 - AUTO POSTO ANCHIETA LTDA | N12: =COUNTIF(B12:G12,"AO VIVO")*12+COUNTIF(B12:G12,"EAD")*8+COUNTIF(H12:M12,"AO VIVO")*12+COUNTIF(H12:M12,"EAD")*8 -> 0
A13: 6357 - AUTO POSTO DIONISIO LTDA | N13: =COUNTIF(B13:G13,"AO VIVO")*12+COUNTIF(B13:G13,"EAD")*8+COUNTIF(H13:M13,"AO VIVO")*12+COUNTIF(H13:M13,"EAD")*8 -> 0
A14: 11839 - COMERCIO DE COMBUSTIVEIS BARRA DO JACARE LTDA | N14: =COUNTIF(B14:G14,"AO VIVO")*12+COUNTIF(B14:G14,"EAD")*8+COUNTIF(H14:M14,"AO VIVO")*12+COUNTIF(H14:M14,"EAD")*8 -> 0
A15: 13450 - DANIELI E DANIELI AUTO POSTO | N15: =COUNTIF(B15:G15,"AO VIVO")*12+COUNTIF(B15:G15,"EAD")*8+COUNTIF(H15:M15,"AO VIVO")*12+COUNTIF(H15:M15,"EAD")*8 -> 0
A16: 4266 - POSTO XAVIER E XAVIER LTDA | N16: =COUNTIF(B16:G16,"AO VIVO")*12+COUNTIF(B16:G16,"EAD")*8+COUNTIF(H16:M16,"AO VIVO")*12+COUNTIF(H16:M16,"EAD")*8 -> 0
A17: 12380 - LEKALL COMERCIO E DISTRIBUICAO DE COMBUSTIVEIS LTDA | N17: =COUNTIF(B17:G17,"AO VIVO")*12+COUNTIF(B17:G17,"EAD")*8+COUNTIF(H17:M17,"AO VIVO")*12+COUNTIF(H17:M17,"EAD")*8 -> 0
A18: 667 - ANSILIERO E NAVA LTDA ME | N18: =COUNTIF(B18:G18,"AO VIVO")*12+COUNTIF(B18:G18,"EAD")*8+COUNTIF(H18:M18,"AO VIVO")*12+COUNTIF(H18:M18,"EAD")*8 -> 0
A19: 12181 - POSTO JK DERIVADOS DE PETROLEO LTDA | N19: =COUNTIF(B19:G19,"AO VIVO")*12+COUNTIF(B19:G19,"EAD")*8+COUNTIF(H19:M19,"AO VIVO")*12+COUNTIF(H19:M19,"EAD")*8 -> 0
A20: 13968 - MARIA DAS MERCES DE SA OLIVEIRA BATISTA DE ABREU LTDA MATRIZ | N20: =COUNTIF(B20:G20,"AO VIVO")*12+COUNTIF(B20:G20,"EAD")*8+COUNTIF(H20:M20,"AO VIVO")*12+COUNTIF(H20:M20,"EAD")*8 -> 0
A21: 13969 - MARIA DAS MERCES DE SA OLIVEIRA BATISTA DE ABREU LTDA FILIAL | N21: =COUNTIF(B21:G21,"AO VIVO")*12+COUNTIF(B21:G21,"EAD")*8+COUNTIF(H21:M21,"AO VIVO")*12+COUNTIF(H21:M21,"EAD")*8 -> 0
A22: 8571 - COMERCIAL DE COMBUSTIVEIS RG LTDA | N22: =COUNTIF(B22:G22,"AO VIVO")*12+COUNTIF(B22:G22,"EAD")*8+COUNTIF(H22:M22,"AO VIVO")*12+COUNTIF(H22:M22,"EAD")*8 -> 0
A23: 11088 - POSTO CENTRAL GUARANIACU LTDA | B23: AO VIVO | N23: =COUNTIF(B23:G23,"AO VIVO")*12+COUNTIF(B23:G23,"EAD")*8+COUNTIF(H23:M23,"AO VIVO")*12+COUNTIF(H23:M23,"EAD")*8 -> 12
A24: 5264 - AUTO POSTO BOM JESUS ITAIOPOLIS LTDA | N24: =COUNTIF(B24:G24,"AO VIVO")*12+COUNTIF(B24:G24,"EAD")*8+COUNTIF(H24:M24,"AO VIVO")*12+COUNTIF(H24:M24,"EAD")*8 -> 0
A25: 11636 - PETROMULLER ABASTECEDORA CASCATA LTDA | N25: =COUNTIF(B25:G25,"AO VIVO")*12+COUNTIF(B25:G25,"EAD")*8+COUNTIF(H25:M25,"AO VIVO")*12+COUNTIF(H25:M25,"EAD")*8 -> 0
A26: 11403 - POSTO SENHOR DO BONFIM LTDA | N26: =COUNTIF(B26:G26,"AO VIVO")*12+COUNTIF(B26:G26,"EAD")*8+COUNTIF(H26:M26,"AO VIVO")*12+COUNTIF(H26:M26,"EAD")*8 -> 0
A27: 5149 - POSTO DE COMBUSTIVEIS PARQUE LTDA EPP | N27: =COUNTIF(B27:G27,"AO VIVO")*12+COUNTIF(B27:G27,"EAD")*8+COUNTIF(H27:M27,"AO VIVO")*12+COUNTIF(H27:M27,"EAD")*8 -> 0
A28: 3139 - POSTO SANTOS E SILVA LTDA | B28: AO VIVO | N28: =COUNTIF(B28:G28,"AO VIVO")*12+COUNTIF(B28:G28,"EAD")*8+COUNTIF(H28:M28,"AO VIVO")*12+COUNTIF(H28:M28,"EAD")*8 -> 12
A29: 5953 - COMERCIO DE COMBUSTIVEIS OLCZEWSKI LTDA EPP | C29: AO VIVO | N29: =COUNTIF(B29:G29,"AO VIVO")*12+COUNTIF(B29:G29,"EAD")*8+COUNTIF(H29:M29,"AO VIVO")*12+COUNTIF(H29:M29,"EAD")*8 -> 12
A30: 14033 - HS COMERCIO DE COMBUSTIVEIS LTDA | B30: AO VIVO | C30: AO VIVO | N30: =COUNTIF(B30:G30,"AO VIVO")*12+COUNTIF(B30:G30,"EAD")*8+COUNTIF(H30:M30,"AO VIVO")*12+COUNTIF(H30:M30,"EAD")*8 -> 24
A31: 13516 - AUTO POSTO FORTI CORSE LTDA | N31: =COUNTIF(B31:G31,"AO VIVO")*12+COUNTIF(B31:G31,"EAD")*8+COUNTIF(H31:M31,"AO VIVO")*12+COUNTIF(H31:M31,"EAD")*8 -> 0
A32: 12305 - ROBERTO AZAMBUJA LTDA | B32: AO VIVO | C32: AO VIVO | N32: =COUNTIF(B32:G32,"AO VIVO")*12+COUNTIF(B32:G32,"EAD")*8+COUNTIF(H32:M32,"AO VIVO")*12+COUNTIF(H32:M32,"EAD")*8 -> 24
A33: 6701 - AUTO POSTO MARIA RITA LTDA | B33: AO VIVO | N33: =COUNTIF(B33:G33,"AO VIVO")*12+COUNTIF(B33:G33,"EAD")*8+COUNTIF(H33:M33,"AO VIVO")*12+COUNTIF(H33:M33,"EAD")*8 -> 12
A34: 9262 - EXCELENCIA EM COMBUSTIVEIS IRANI LTDA | B34: AO VIVO | C34: AO VIVO | N34: =COUNTIF(B34:G34,"AO VIVO")*12+COUNTIF(B34:G34,"EAD")*8+COUNTIF(H34:M34,"AO VIVO")*12+COUNTIF(H34:M34,"EAD")*8 -> 24
A35: 9617 - AUTO POSTO MACHADO E VIEIRA LTDA | N35: =COUNTIF(B35:G35,"AO VIVO")*12+COUNTIF(B35:G35,"EAD")*8+COUNTIF(H35:M35,"AO VIVO")*12+COUNTIF(H35:M35,"EAD")*8 -> 0
A36: 8314 - COMBUSTIVEIS E CONVENIENCIA OKATA LTDA | N36: =COUNTIF(B36:G36,"AO VIVO")*12+COUNTIF(B36:G36,"EAD")*8+COUNTIF(H36:M36,"AO VIVO")*12+COUNTIF(H36:M36,"EAD")*8 -> 0
A37: 5005 - POSTO TOP HAMMER LTDA | N37: =COUNTIF(B37:G37,"AO VIVO")*12+COUNTIF(B37:G37,"EAD")*8+COUNTIF(H37:M37,"AO VIVO")*12+COUNTIF(H37:M37,"EAD")*8 -> 0
A38: 6481 - A COIMBRA PEPECE & CIA LTDA | B38: AO VIVO | N38: =COUNTIF(B38:G38,"AO VIVO")*12+COUNTIF(B38:G38,"EAD")*8+COUNTIF(H38:M38,"AO VIVO")*12+COUNTIF(H38:M38,"EAD")*8 -> 12
A39: 5755 - FARINA COMERCIO DE COMBUSTIVEIS E LUBRIFICANTES LTDA | N39: =COUNTIF(B39:G39,"AO VIVO")*12+COUNTIF(B39:G39,"EAD")*8+COUNTIF(H39:M39,"AO VIVO")*12+COUNTIF(H39:M39,"EAD")*8 -> 0
A40: POSTO BATEL LTDA | N40: =COUNTIF(B40:G40,"AO VIVO")*12+COUNTIF(B40:G40,"EAD")*8+COUNTIF(H40:M40,"AO VIVO")*12+COUNTIF(H40:M40,"EAD")*8 -> 0
...

Sheet Litragem
A1: Nome dos Postos | B1: Litragem 2026 | N1: Total Pontos Combustíveis
B2: Janeiro | C2: Fevereiro | D2: Março | E2: Abril | F2: Maio | G2: Junho | H2: Julho | I2: Agosto | J2: Setembro | K2: Outubro | L2: Novembro | M2: Dezembro
A3: 7784 - ROSANE BERSCH HARTWIG ME - FILIAL 01 | N3: =IF(B88<>0,MAX(0,INT(((SUM(B3:M3)/B88)-1)*100)*12),0) -> 0
A4: 11928 - MARCOS ALFREDO POZZEBON | N4: =IF(B89<>0,MAX(0,INT(((SUM(B4:M4)/B89)-1)*100)*12),0) -> 0
A5: 11386 - COMERCIO DE COMBUSTIVEIS ITATIBENSE LTDA | N5: =IF(B90<>0,MAX(0,INT(((SUM(B5:M5)/B90)-1)*100)*12),0) -> 0
A6: 10389 - AUTO POSTO ABREU LTDA | N6: =IF(B91<>0,MAX(0,INT(((SUM(B6:M6)/B91)-1)*100)*12),0) -> 0
A7: 3999 - POSTO ROSINSKI LTDA | N7: =IF(B92<>0,MAX(0,INT(((SUM(B7:M7)/B92)-1)*100)*12),0) -> 0
A8: 1283 - MARILEI DE FATIMA ALT LTDA | N8: =IF(B93<>0,MAX(0,INT(((SUM(B8:M8)/B93)-1)*100)*12),0) -> 0
A9: 4735 - AUTO POSTO CASTELLO LTDA | N9: =IF(B94<>0,MAX(0,INT(((SUM(B9:M9)/B94)-1)*100)*12),0) -> 0
A10: 8622 - COOP MISTA DA AGRIC FAMILIAR DE SAO JOAO DO OESTE COOPAFASJO | N10: =IF(B95<>0,MAX(0,INT(((SUM(B10:M10)/B95)-1)*100)*12),0) -> 0
A11: 2664 - AUTO POSTO ANCHIETA LTDA | N11: =IF(B96<>0,MAX(0,INT(((SUM(B11:M11)/B96)-1)*100)*12),0) -> 0
A12: 6357 - AUTO POSTO DIONISIO LTDA | N12: =IF(B97<>0,MAX(0,INT(((SUM(B12:M12)/B97)-1)*100)*12),0) -> 0
A13: 11839 - COMERCIO DE COMBUSTIVEIS BARRA DO JACARE LTDA | N13: =IF(B98<>0,MAX(0,INT(((SUM(B13:M13)/B98)-1)*100)*12),0) -> 0
A14: 13450 - DANIELI E DANIELI AUTO POSTO | N14: =IF(B99<>0,MAX(0,INT(((SUM(B14:M14)/B99)-1)*100)*12),0) -> 0
... A84: 4687 - COMERCIO DE COMBUSTIVEIS ROBERTINHO LTDA | N84: =IF(B169<>0,MAX(0,INT(((SUM(B84:M84)/B169)-1)*100)*12),0) -> 0
A86: Nome dos Postos | B86: Litragem 2025
A88: 7784 - ROSANE BERSCH HARTWIG ME - FILIAL 01
A89: 11928 - MARCOS ALFREDO POZZEBON
A90: 11386 - COMERCIO DE COMBUSTIVEIS ITATIBENSE LTDA
A91: 10389 - AUTO POSTO ABREU LTDA
A92: 3999 - POSTO ROSINSKI LTDA
A93: 1283 - MARILEI DE FATIMA ALT LTDA
A94: 4735 - AUTO POSTO CASTELLO LTDA
A95: 8622 - COOP MISTA DA AGRIC FAMILIAR DE SAO JOAO DO OESTE COOPAFASJO
A96: 2664 - AUTO POSTO ANCHIETA LTDA
A97: 6357 - AUTO POSTO DIONISIO LTDA
A98: 11839 - COMERCIO DE COMBUSTIVEIS BARRA DO JACARE LTDA
A99: 13450 - DANIELI E DANIELI AUTO POSTO
... A169: 4687 - COMERCIO DE COMBUSTIVEIS ROBERTINHO LTDA
